<?xml version="1.0" encoding="UTF-8"?>
<testng-results skipped="0" failed="6" total="10" passed="4">
  <reporter-output>
  </reporter-output>
  <suite name="Default suite" duration-ms="62876" started-at="2015-12-14T18:29:43Z" finished-at="2015-12-14T18:30:46Z">
    <groups>
    </groups>
    <test name="Default test" duration-ms="62876" started-at="2015-12-14T18:29:43Z" finished-at="2015-12-14T18:30:46Z">
      <class name="testcases.CostosBudgetRompeFiltro">
        <test-method status="PASS" signature="beforeMethod()[pri:0, instance:testcases.CostosBudgetRompeFiltro@3b6eb2ec]" name="beforeMethod" is-config="true" duration-ms="8783" started-at="2015-12-14T15:29:34Z" finished-at="2015-12-14T15:29:43Z">
          <reporter-output>
          </reporter-output>
        </test-method> <!-- beforeMethod -->
        <test-method status="PASS" signature="testLoginUserValidoAdmin()[pri:0, instance:testcases.CostosBudgetRompeFiltro@3b6eb2ec]" name="testLoginUserValidoAdmin" duration-ms="6145" started-at="2015-12-14T15:29:43Z" finished-at="2015-12-14T15:29:49Z">
          <reporter-output>
          </reporter-output>
        </test-method> <!-- testLoginUserValidoAdmin -->
        <test-method status="FAIL" signature="costosBudgetSeteoBloqueadoNo()[pri:0, instance:testcases.CostosBudgetRompeFiltro@3b6eb2ec]" name="costosBudgetSeteoBloqueadoNo" duration-ms="6991" started-at="2015-12-14T15:29:49Z" depends-on-methods="testcases.CostosBudgetRompeFiltro.testLoginUserValidoAdmin" finished-at="2015-12-14T15:29:56Z">
          <exception class="java.lang.AssertionError">
            <message>
              <![CDATA[expected [MeadJohnson] but found [Database Exception – yii\db\Exception]]]>
            </message>
            <full-stacktrace>
              <![CDATA[java.lang.AssertionError: expected [MeadJohnson] but found [Database Exception – yii\db\Exception]
	at org.testng.Assert.fail(Assert.java:94)
	at org.testng.Assert.failNotEquals(Assert.java:496)
	at org.testng.Assert.assertEquals(Assert.java:125)
	at org.testng.Assert.assertEquals(Assert.java:178)
	at org.testng.Assert.assertEquals(Assert.java:188)
	at testcases.CostosBudgetRompeFiltro.costosBudgetSeteoBloqueadoNo(CostosBudgetRompeFiltro.java:78)
	at sun.reflect.NativeMethodAccessorImpl.invoke0(Native Method)
	at sun.reflect.NativeMethodAccessorImpl.invoke(Unknown Source)
	at sun.reflect.DelegatingMethodAccessorImpl.invoke(Unknown Source)
	at java.lang.reflect.Method.invoke(Unknown Source)
	at org.testng.internal.MethodInvocationHelper.invokeMethod(MethodInvocationHelper.java:86)
	at org.testng.internal.Invoker.invokeMethod(Invoker.java:643)
	at org.testng.internal.Invoker.invokeTestMethod(Invoker.java:820)
	at org.testng.internal.Invoker.invokeTestMethods(Invoker.java:1128)
	at org.testng.internal.TestMethodWorker.invokeTestMethods(TestMethodWorker.java:129)
	at org.testng.internal.TestMethodWorker.run(TestMethodWorker.java:112)
	at org.testng.TestRunner.privateRun(TestRunner.java:782)
	at org.testng.TestRunner.run(TestRunner.java:632)
	at org.testng.SuiteRunner.runTest(SuiteRunner.java:366)
	at org.testng.SuiteRunner.runSequentially(SuiteRunner.java:361)
	at org.testng.SuiteRunner.privateRun(SuiteRunner.java:319)
	at org.testng.SuiteRunner.run(SuiteRunner.java:268)
	at org.testng.SuiteRunnerWorker.runSuite(SuiteRunnerWorker.java:52)
	at org.testng.SuiteRunnerWorker.run(SuiteRunnerWorker.java:86)
	at org.testng.TestNG.runSuitesSequentially(TestNG.java:1246)
	at org.testng.TestNG.runSuitesLocally(TestNG.java:1171)
	at org.testng.TestNG.run(TestNG.java:1066)
	at org.testng.remote.RemoteTestNG.run(RemoteTestNG.java:113)
	at org.testng.remote.RemoteTestNG.initAndRun(RemoteTestNG.java:206)
	at org.testng.remote.RemoteTestNG.main(RemoteTestNG.java:177)
]]>
            </full-stacktrace>
          </exception> <!-- java.lang.AssertionError -->
          <reporter-output>
          </reporter-output>
        </test-method> <!-- costosBudgetSeteoBloqueadoNo -->
        <test-method status="FAIL" signature="costosBudgetSeteoBloqueadoSi()[pri:0, instance:testcases.CostosBudgetRompeFiltro@3b6eb2ec]" name="costosBudgetSeteoBloqueadoSi" duration-ms="6819" started-at="2015-12-14T15:29:56Z" depends-on-methods="testcases.CostosBudgetRompeFiltro.testLoginUserValidoAdmin" finished-at="2015-12-14T15:30:03Z">
          <exception class="java.lang.AssertionError">
            <message>
              <![CDATA[expected [MeadJohnson] but found [Database Exception – yii\db\Exception]]]>
            </message>
            <full-stacktrace>
              <![CDATA[java.lang.AssertionError: expected [MeadJohnson] but found [Database Exception – yii\db\Exception]
	at org.testng.Assert.fail(Assert.java:94)
	at org.testng.Assert.failNotEquals(Assert.java:496)
	at org.testng.Assert.assertEquals(Assert.java:125)
	at org.testng.Assert.assertEquals(Assert.java:178)
	at org.testng.Assert.assertEquals(Assert.java:188)
	at testcases.CostosBudgetRompeFiltro.costosBudgetSeteoBloqueadoSi(CostosBudgetRompeFiltro.java:54)
	at sun.reflect.NativeMethodAccessorImpl.invoke0(Native Method)
	at sun.reflect.NativeMethodAccessorImpl.invoke(Unknown Source)
	at sun.reflect.DelegatingMethodAccessorImpl.invoke(Unknown Source)
	at java.lang.reflect.Method.invoke(Unknown Source)
	at org.testng.internal.MethodInvocationHelper.invokeMethod(MethodInvocationHelper.java:86)
	at org.testng.internal.Invoker.invokeMethod(Invoker.java:643)
	at org.testng.internal.Invoker.invokeTestMethod(Invoker.java:820)
	at org.testng.internal.Invoker.invokeTestMethods(Invoker.java:1128)
	at org.testng.internal.TestMethodWorker.invokeTestMethods(TestMethodWorker.java:129)
	at org.testng.internal.TestMethodWorker.run(TestMethodWorker.java:112)
	at org.testng.TestRunner.privateRun(TestRunner.java:782)
	at org.testng.TestRunner.run(TestRunner.java:632)
	at org.testng.SuiteRunner.runTest(SuiteRunner.java:366)
	at org.testng.SuiteRunner.runSequentially(SuiteRunner.java:361)
	at org.testng.SuiteRunner.privateRun(SuiteRunner.java:319)
	at org.testng.SuiteRunner.run(SuiteRunner.java:268)
	at org.testng.SuiteRunnerWorker.runSuite(SuiteRunnerWorker.java:52)
	at org.testng.SuiteRunnerWorker.run(SuiteRunnerWorker.java:86)
	at org.testng.TestNG.runSuitesSequentially(TestNG.java:1246)
	at org.testng.TestNG.runSuitesLocally(TestNG.java:1171)
	at org.testng.TestNG.run(TestNG.java:1066)
	at org.testng.remote.RemoteTestNG.run(RemoteTestNG.java:113)
	at org.testng.remote.RemoteTestNG.initAndRun(RemoteTestNG.java:206)
	at org.testng.remote.RemoteTestNG.main(RemoteTestNG.java:177)
]]>
            </full-stacktrace>
          </exception> <!-- java.lang.AssertionError -->
          <reporter-output>
          </reporter-output>
        </test-method> <!-- costosBudgetSeteoBloqueadoSi -->
        <test-method status="FAIL" signature="costosBudgetSeteoCampoAnio1()[pri:0, instance:testcases.CostosBudgetRompeFiltro@3b6eb2ec]" name="costosBudgetSeteoCampoAnio1" duration-ms="6029" started-at="2015-12-14T15:30:03Z" depends-on-methods="testcases.CostosBudgetRompeFiltro.testLoginUserValidoAdmin" finished-at="2015-12-14T15:30:09Z">
          <exception class="java.lang.AssertionError">
            <message>
              <![CDATA[expected [MeadJohnson] but found [Database Exception – yii\db\Exception]]]>
            </message>
            <full-stacktrace>
              <![CDATA[java.lang.AssertionError: expected [MeadJohnson] but found [Database Exception – yii\db\Exception]
	at org.testng.Assert.fail(Assert.java:94)
	at org.testng.Assert.failNotEquals(Assert.java:496)
	at org.testng.Assert.assertEquals(Assert.java:125)
	at org.testng.Assert.assertEquals(Assert.java:178)
	at org.testng.Assert.assertEquals(Assert.java:188)
	at testcases.CostosBudgetRompeFiltro.costosBudgetSeteoCampoAnio1(CostosBudgetRompeFiltro.java:136)
	at sun.reflect.NativeMethodAccessorImpl.invoke0(Native Method)
	at sun.reflect.NativeMethodAccessorImpl.invoke(Unknown Source)
	at sun.reflect.DelegatingMethodAccessorImpl.invoke(Unknown Source)
	at java.lang.reflect.Method.invoke(Unknown Source)
	at org.testng.internal.MethodInvocationHelper.invokeMethod(MethodInvocationHelper.java:86)
	at org.testng.internal.Invoker.invokeMethod(Invoker.java:643)
	at org.testng.internal.Invoker.invokeTestMethod(Invoker.java:820)
	at org.testng.internal.Invoker.invokeTestMethods(Invoker.java:1128)
	at org.testng.internal.TestMethodWorker.invokeTestMethods(TestMethodWorker.java:129)
	at org.testng.internal.TestMethodWorker.run(TestMethodWorker.java:112)
	at org.testng.TestRunner.privateRun(TestRunner.java:782)
	at org.testng.TestRunner.run(TestRunner.java:632)
	at org.testng.SuiteRunner.runTest(SuiteRunner.java:366)
	at org.testng.SuiteRunner.runSequentially(SuiteRunner.java:361)
	at org.testng.SuiteRunner.privateRun(SuiteRunner.java:319)
	at org.testng.SuiteRunner.run(SuiteRunner.java:268)
	at org.testng.SuiteRunnerWorker.runSuite(SuiteRunnerWorker.java:52)
	at org.testng.SuiteRunnerWorker.run(SuiteRunnerWorker.java:86)
	at org.testng.TestNG.runSuitesSequentially(TestNG.java:1246)
	at org.testng.TestNG.runSuitesLocally(TestNG.java:1171)
	at org.testng.TestNG.run(TestNG.java:1066)
	at org.testng.remote.RemoteTestNG.run(RemoteTestNG.java:113)
	at org.testng.remote.RemoteTestNG.initAndRun(RemoteTestNG.java:206)
	at org.testng.remote.RemoteTestNG.main(RemoteTestNG.java:177)
]]>
            </full-stacktrace>
          </exception> <!-- java.lang.AssertionError -->
          <reporter-output>
          </reporter-output>
        </test-method> <!-- costosBudgetSeteoCampoAnio1 -->
        <test-method status="PASS" signature="costosBudgetSeteoCampoAnio2()[pri:0, instance:testcases.CostosBudgetRompeFiltro@3b6eb2ec]" name="costosBudgetSeteoCampoAnio2" duration-ms="6216" started-at="2015-12-14T15:30:09Z" depends-on-methods="testcases.CostosBudgetRompeFiltro.testLoginUserValidoAdmin" finished-at="2015-12-14T15:30:15Z">
          <reporter-output>
          </reporter-output>
        </test-method> <!-- costosBudgetSeteoCampoAnio2 -->
        <test-method status="PASS" signature="costosBudgetSeteoCampoAnio3()[pri:0, instance:testcases.CostosBudgetRompeFiltro@3b6eb2ec]" name="costosBudgetSeteoCampoAnio3" duration-ms="6061" started-at="2015-12-14T15:30:15Z" depends-on-methods="testcases.CostosBudgetRompeFiltro.testLoginUserValidoAdmin" finished-at="2015-12-14T15:30:21Z">
          <reporter-output>
          </reporter-output>
        </test-method> <!-- costosBudgetSeteoCampoAnio3 -->
        <test-method status="FAIL" signature="costosBudgetSeteoCampoDescripcion1()[pri:0, instance:testcases.CostosBudgetRompeFiltro@3b6eb2ec]" name="costosBudgetSeteoCampoDescripcion1" duration-ms="6086" started-at="2015-12-14T15:30:21Z" depends-on-methods="testcases.CostosBudgetRompeFiltro.testLoginUserValidoAdmin" finished-at="2015-12-14T15:30:27Z">
          <exception class="java.lang.AssertionError">
            <message>
              <![CDATA[expected [MeadJohnson] but found [Database Exception – yii\db\Exception]]]>
            </message>
            <full-stacktrace>
              <![CDATA[java.lang.AssertionError: expected [MeadJohnson] but found [Database Exception – yii\db\Exception]
	at org.testng.Assert.fail(Assert.java:94)
	at org.testng.Assert.failNotEquals(Assert.java:496)
	at org.testng.Assert.assertEquals(Assert.java:125)
	at org.testng.Assert.assertEquals(Assert.java:178)
	at org.testng.Assert.assertEquals(Assert.java:188)
	at testcases.CostosBudgetRompeFiltro.costosBudgetSeteoCampoDescripcion1(CostosBudgetRompeFiltro.java:90)
	at sun.reflect.NativeMethodAccessorImpl.invoke0(Native Method)
	at sun.reflect.NativeMethodAccessorImpl.invoke(Unknown Source)
	at sun.reflect.DelegatingMethodAccessorImpl.invoke(Unknown Source)
	at java.lang.reflect.Method.invoke(Unknown Source)
	at org.testng.internal.MethodInvocationHelper.invokeMethod(MethodInvocationHelper.java:86)
	at org.testng.internal.Invoker.invokeMethod(Invoker.java:643)
	at org.testng.internal.Invoker.invokeTestMethod(Invoker.java:820)
	at org.testng.internal.Invoker.invokeTestMethods(Invoker.java:1128)
	at org.testng.internal.TestMethodWorker.invokeTestMethods(TestMethodWorker.java:129)
	at org.testng.internal.TestMethodWorker.run(TestMethodWorker.java:112)
	at org.testng.TestRunner.privateRun(TestRunner.java:782)
	at org.testng.TestRunner.run(TestRunner.java:632)
	at org.testng.SuiteRunner.runTest(SuiteRunner.java:366)
	at org.testng.SuiteRunner.runSequentially(SuiteRunner.java:361)
	at org.testng.SuiteRunner.privateRun(SuiteRunner.java:319)
	at org.testng.SuiteRunner.run(SuiteRunner.java:268)
	at org.testng.SuiteRunnerWorker.runSuite(SuiteRunnerWorker.java:52)
	at org.testng.SuiteRunnerWorker.run(SuiteRunnerWorker.java:86)
	at org.testng.TestNG.runSuitesSequentially(TestNG.java:1246)
	at org.testng.TestNG.runSuitesLocally(TestNG.java:1171)
	at org.testng.TestNG.run(TestNG.java:1066)
	at org.testng.remote.RemoteTestNG.run(RemoteTestNG.java:113)
	at org.testng.remote.RemoteTestNG.initAndRun(RemoteTestNG.java:206)
	at org.testng.remote.RemoteTestNG.main(RemoteTestNG.java:177)
]]>
            </full-stacktrace>
          </exception> <!-- java.lang.AssertionError -->
          <reporter-output>
          </reporter-output>
        </test-method> <!-- costosBudgetSeteoCampoDescripcion1 -->
        <test-method status="FAIL" signature="costosBudgetSeteoCampoDescripcion2()[pri:0, instance:testcases.CostosBudgetRompeFiltro@3b6eb2ec]" name="costosBudgetSeteoCampoDescripcion2" duration-ms="6115" started-at="2015-12-14T15:30:27Z" depends-on-methods="testcases.CostosBudgetRompeFiltro.testLoginUserValidoAdmin" finished-at="2015-12-14T15:30:33Z">
          <exception class="java.lang.AssertionError">
            <message>
              <![CDATA[expected [MeadJohnson] but found [Database Exception – yii\db\Exception]]]>
            </message>
            <full-stacktrace>
              <![CDATA[java.lang.AssertionError: expected [MeadJohnson] but found [Database Exception – yii\db\Exception]
	at org.testng.Assert.fail(Assert.java:94)
	at org.testng.Assert.failNotEquals(Assert.java:496)
	at org.testng.Assert.assertEquals(Assert.java:125)
	at org.testng.Assert.assertEquals(Assert.java:178)
	at org.testng.Assert.assertEquals(Assert.java:188)
	at testcases.CostosBudgetRompeFiltro.costosBudgetSeteoCampoDescripcion2(CostosBudgetRompeFiltro.java:102)
	at sun.reflect.NativeMethodAccessorImpl.invoke0(Native Method)
	at sun.reflect.NativeMethodAccessorImpl.invoke(Unknown Source)
	at sun.reflect.DelegatingMethodAccessorImpl.invoke(Unknown Source)
	at java.lang.reflect.Method.invoke(Unknown Source)
	at org.testng.internal.MethodInvocationHelper.invokeMethod(MethodInvocationHelper.java:86)
	at org.testng.internal.Invoker.invokeMethod(Invoker.java:643)
	at org.testng.internal.Invoker.invokeTestMethod(Invoker.java:820)
	at org.testng.internal.Invoker.invokeTestMethods(Invoker.java:1128)
	at org.testng.internal.TestMethodWorker.invokeTestMethods(TestMethodWorker.java:129)
	at org.testng.internal.TestMethodWorker.run(TestMethodWorker.java:112)
	at org.testng.TestRunner.privateRun(TestRunner.java:782)
	at org.testng.TestRunner.run(TestRunner.java:632)
	at org.testng.SuiteRunner.runTest(SuiteRunner.java:366)
	at org.testng.SuiteRunner.runSequentially(SuiteRunner.java:361)
	at org.testng.SuiteRunner.privateRun(SuiteRunner.java:319)
	at org.testng.SuiteRunner.run(SuiteRunner.java:268)
	at org.testng.SuiteRunnerWorker.runSuite(SuiteRunnerWorker.java:52)
	at org.testng.SuiteRunnerWorker.run(SuiteRunnerWorker.java:86)
	at org.testng.TestNG.runSuitesSequentially(TestNG.java:1246)
	at org.testng.TestNG.runSuitesLocally(TestNG.java:1171)
	at org.testng.TestNG.run(TestNG.java:1066)
	at org.testng.remote.RemoteTestNG.run(RemoteTestNG.java:113)
	at org.testng.remote.RemoteTestNG.initAndRun(RemoteTestNG.java:206)
	at org.testng.remote.RemoteTestNG.main(RemoteTestNG.java:177)
]]>
            </full-stacktrace>
          </exception> <!-- java.lang.AssertionError -->
          <reporter-output>
          </reporter-output>
        </test-method> <!-- costosBudgetSeteoCampoDescripcion2 -->
        <test-method status="FAIL" signature="costosBudgetSeteoCampoDescripcion3()[pri:0, instance:testcases.CostosBudgetRompeFiltro@3b6eb2ec]" name="costosBudgetSeteoCampoDescripcion3" duration-ms="6268" started-at="2015-12-14T15:30:33Z" depends-on-methods="testcases.CostosBudgetRompeFiltro.testLoginUserValidoAdmin" finished-at="2015-12-14T15:30:40Z">
          <exception class="java.lang.AssertionError">
            <message>
              <![CDATA[expected [MeadJohnson] but found [Database Exception – yii\db\Exception]]]>
            </message>
            <full-stacktrace>
              <![CDATA[java.lang.AssertionError: expected [MeadJohnson] but found [Database Exception – yii\db\Exception]
	at org.testng.Assert.fail(Assert.java:94)
	at org.testng.Assert.failNotEquals(Assert.java:496)
	at org.testng.Assert.assertEquals(Assert.java:125)
	at org.testng.Assert.assertEquals(Assert.java:178)
	at org.testng.Assert.assertEquals(Assert.java:188)
	at testcases.CostosBudgetRompeFiltro.costosBudgetSeteoCampoDescripcion3(CostosBudgetRompeFiltro.java:114)
	at sun.reflect.NativeMethodAccessorImpl.invoke0(Native Method)
	at sun.reflect.NativeMethodAccessorImpl.invoke(Unknown Source)
	at sun.reflect.DelegatingMethodAccessorImpl.invoke(Unknown Source)
	at java.lang.reflect.Method.invoke(Unknown Source)
	at org.testng.internal.MethodInvocationHelper.invokeMethod(MethodInvocationHelper.java:86)
	at org.testng.internal.Invoker.invokeMethod(Invoker.java:643)
	at org.testng.internal.Invoker.invokeTestMethod(Invoker.java:820)
	at org.testng.internal.Invoker.invokeTestMethods(Invoker.java:1128)
	at org.testng.internal.TestMethodWorker.invokeTestMethods(TestMethodWorker.java:129)
	at org.testng.internal.TestMethodWorker.run(TestMethodWorker.java:112)
	at org.testng.TestRunner.privateRun(TestRunner.java:782)
	at org.testng.TestRunner.run(TestRunner.java:632)
	at org.testng.SuiteRunner.runTest(SuiteRunner.java:366)
	at org.testng.SuiteRunner.runSequentially(SuiteRunner.java:361)
	at org.testng.SuiteRunner.privateRun(SuiteRunner.java:319)
	at org.testng.SuiteRunner.run(SuiteRunner.java:268)
	at org.testng.SuiteRunnerWorker.runSuite(SuiteRunnerWorker.java:52)
	at org.testng.SuiteRunnerWorker.run(SuiteRunnerWorker.java:86)
	at org.testng.TestNG.runSuitesSequentially(TestNG.java:1246)
	at org.testng.TestNG.runSuitesLocally(TestNG.java:1171)
	at org.testng.TestNG.run(TestNG.java:1066)
	at org.testng.remote.RemoteTestNG.run(RemoteTestNG.java:113)
	at org.testng.remote.RemoteTestNG.initAndRun(RemoteTestNG.java:206)
	at org.testng.remote.RemoteTestNG.main(RemoteTestNG.java:177)
]]>
            </full-stacktrace>
          </exception> <!-- java.lang.AssertionError -->
          <reporter-output>
          </reporter-output>
        </test-method> <!-- costosBudgetSeteoCampoDescripcion3 -->
        <test-method status="PASS" signature="costosBudgetSeteoCampoDescripcion4()[pri:0, instance:testcases.CostosBudgetRompeFiltro@3b6eb2ec]" name="costosBudgetSeteoCampoDescripcion4" duration-ms="6087" started-at="2015-12-14T15:30:40Z" depends-on-methods="testcases.CostosBudgetRompeFiltro.testLoginUserValidoAdmin" finished-at="2015-12-14T15:30:46Z">
          <reporter-output>
          </reporter-output>
        </test-method> <!-- costosBudgetSeteoCampoDescripcion4 -->
        <test-method status="PASS" signature="afterMethod()[pri:0, instance:testcases.CostosBudgetRompeFiltro@3b6eb2ec]" name="afterMethod" is-config="true" duration-ms="686" started-at="2015-12-14T15:30:46Z" finished-at="2015-12-14T15:30:46Z">
          <reporter-output>
          </reporter-output>
        </test-method> <!-- afterMethod -->
      </class> <!-- testcases.CostosBudgetRompeFiltro -->
    </test> <!-- Default test -->
  </suite> <!-- Default suite -->
</testng-results>
